Workbook
Name CONN.: #REF!

Sheet 表頭
A2: 治具製作流程單 | H2: 客戶名稱： | I2: =LIST!F1 -> 景碩科技 清華廠
A3: 工 單 | B3: =LIST!E1 -> WD-2601007 | D3: 訂單日 | E3: =LIST!B1 -> 1/3 | G3: 完成日 | H3: =LIST!C1 -> 1/11 | I3: 送達日 | K3: =LIST!D1 -> 1/12
A4: 料 號 | B4: =LIST!G1 -> Q59-859-1(2+4W) | G4: 機 種 | H4: =LIST!H1 -> Gats-77XX | I4: 業 務 | K4: 陳慧婷
A5: 備 註 | B5: "1.備品針各10支 2.附上下治具AB&FG墊片75、50um、25um 各2pcs
A6: 工程設計 | B6: USB NO： | E6: 1074
A7: 針型-pin數 | B7: 上 | E7: 下 | H7: 線徑 | I7: 上 | K7: 下
B8: 40N(3.5) | C8: 2526 | D8: pin | E8: 70N | F8: 706 | G8: pin | I8: ψ | J8: 0.06 | K8: ψ | L8: 0.12
B9: CT46 | I9: DD(Full) | J9: 1 | K9: DD(HALF) | L9: 1
I10: DD(HALF) | J10: 1
A12: 備 註 | H12: 電鍍方式 | I12: 鎳鎢、金、鈀
A13: 鑽孔(NC)
A14: NC DATA | B14: 上： | C14: O2601007.T
B15: 下： | C15: O2601007.B
A16: 電極板 | B16: 治具 | C16: 上 | E16: 下 | G16: UV | H16: 治具 | I16: 上 | K16: 下
B17: 到站時間 | C17: =NOW() -> 46027.723 | E17: =NOW() -> 46027.723 | H17: 到站時間 | I17: =NOW() -> 46027.723 | K17: =NOW() -> 46027.723
B18: 完成時間 | H18: 完成時間
B19: 簽 名 | H19: 簽 名
A20: 備 註
A21: CNC
A22: CNC DATA | B22: TOP-AF Plate、TOP-G Plate、BOT-AF Plate、BOT-G Plate、TOP & BOT-H Plate、上治具組裝圖、下治具組裝圖、手檔板、GATS線蓋（後 )
A24: 電極板成型 | B24: 治具 | C24: 上 | E24: 下 | G24: UV成型 | H24: 治具 | I24: 上 | K24: 下
B25: 到站時間 | H25: 到站時間
B26: 完成時間 | H26: 完成時間
B27: 簽 名 | H27: 簽 名
A28: 電極板研磨 | B28: 到站時間 | G28: Block &附件 | H28: 到站時間
B29: 完成時間 | H29: 完成時間
B30: 簽 名 | H30: 簽 名
A31: 備 註
A32: 組裝
A33: UV插針 | B33: 治具 | C33: 上 | E33: 下 | G33: 焊連 接器 | H33: 治具 | I33: 上 | K33: 下
B34: 到站時間 | H34: 到站時間
B35: 完成時間 | H35: 完成時間
B36: 簽 名 | H36: 簽 名
A38: 電極板配線 | B38: 到站時間 | G38: 點膠 | H38: 到站時間
B39: 完成時間 | H39: 完成時間
B40: 簽 名 | H40: 簽 名
A42: Pin Find | B42: 到站時間 | G42: 電鍍 | H42: 到站時間
B43: 完成時間 | H43: 完成時間
B44: 簽 名 | H44: 簽 名
A46: 測試 | B46: 到站時間 | G46: 組裝 | H46: 到站時間
...

Sheet top-nc
B1: NC DATＡ 管理表 | H1: 40/50針型 F板須挖 火花逃孔0.04~0.05mm | K1: =表頭!B3 -> WD-2601007
A2: 客戶名稱 | C2: =表頭!I2 -> 景碩科技 清華廠 | H2: 製 作 日 期 | K2: =TODAY() -> 46027
A3: 料 號 | C3: =表頭!B4 -> Q59-859-1(2+4W) | H3: 治 具 型 式 | K3: =表頭!H4 -> Gats-77XX | P3: 上治具
A4: 設 計 者 | C4: KS | H4: 鑽孔檔案名稱 | K4: =表頭!C14 -> O2601007.T
A5: 版 本 | C5: GATS-40 | H5: USB NO.
A7: 板材 | B7: SCM8000 | C7: SCM8000 | D7: SCM8000 | E7: R8220 | F7: R8220 | G7: R8220 | H7: R8220 | I7: R8220 | J7: FR4 | K7: FR4 | L7: BOM | M7: BOM | N7: 内容 | P7: 内容 | Q7: 數量
A8: 板厚 | B8: 1.5 | C8: 1 | D8: 0.8 | E8: 1.5 | F8: 3 | G8: 1.5 | H8: 1.5 | I8: 5 | J8: 1 | K8: 10 | L8: 支柱尺寸 | M8: 支柱長度
A9: O NO | B9: A | C9: B | D9: C | E9: D | F9: E | G9: E2 | H9: F | I9: G | J9: G1 | K9: H | O9: T NO
A10: 101 | B10: 0.5深0.5 | C10: 0.5深0.5 | D10: 0.5深0.5 | E10: ― | F10: ― | G10: ― | H10: ― | I10: ― | J10: 1.0深0.5 | K10: ― | O10: =A10-100 -> 1 | P10: ABC原點 | Q10: 1 | R10: AB原點 | S10: 1 | T10: AB原點
A11: =A10+1 -> 102 | B11: ○ | C11: ○ | D11: ○ | E11: ○ | F11: ○ | G11: ○ | H11: ○ | I11: ○ | J11: ― | K11: ― | O11: =A11-100 -> 2 | P11: 測量用 | Q11: 4 | R11: 量測1.0 | S11: 4 | T11: 量測1.0
A12: =A11+1 -> 103 | B12: {=_xlfn._xlws.FILTER('40-3.5-20L'!AD:AP,'40-3.5-20L'!AP:AP='top-nc'!P12)} -> 2 | C12: 2 | D12: 2 | E12: 2 | F12: 2 | G12: 2 | H12: 2 | I12: ― | J12: 2 | K12: ― | L12: 2 | M12: 19 | N12: AF定位PIN-2.0 | O12: =A12-100 -> 3 | P12: =R12 -> AF定位PIN-2.0 | Q12: 4 | R12: AF定位PIN-2.0 | S12: 4 | T12: AF定位PIN-2.0
A13: =A12+1 -> 104 | B13: 2 | C13: ― | D13: ― | E13: ― | F13: ― | G13: ― | H13: ― | I13: ― | J13: ― | K13: ― | L13: ― | N13: 4 | O13: =A13-100 -> 4 | P13: A板挖槽定位PIN | Q13: 4 | R13: A板挖槽定位PIN | S13: 4 | T13: A板挖槽定位PIN
A14: =A13+1 -> 105 | B14: {=_xlfn._xlws.FILTER('40-3.5-20L'!B:N,'40-3.5-20L'!N:N='top-nc'!P14)} -> M1.7沈頭 | C14: 1.8 | D14: 1.8 | E14: 1.8 | F14: 1.8 | G14: 1.8 | H14: M1.7 裏沈頭 | I14: ― | J14: ― | K14: ― | L14: 3 | M14: 9.1 | N14: CD支柱-3.0 | O14: =A14-100 -> 5 | P14: =R14 -> CD支柱-3.0 | Q14: 6 | R14: CD支柱-3.0 | S14: 11 | T14: CD支柱-3.0
A15: =A14+1 -> 106 | B15: 2.0深0.4 /1.2 | C15: 1.3 | D15: 1 | E15: ― | F15: ― | G15: ― | H15: ― | I15: ― | J15: ― | K15: ― | O15: =A15-100 -> 6 | P15: 1.2 CCD | Q15: 2 | R15: 1.2CCD | S15: 2 | T15: 1.2CCD
A16: =A15+1 -> 107 | B16: ― | C16: ― | D16: 0.5深0.5 | E16: ― | F16: ― | G16: 0.5深0.5 | H16: ― | I16: ― | J16: ― | K16: ― | O16: =A16-100 -> 7 | P16: C判別 | Q16: 1 | R16: C判別 | S16: 1 | T16: C判別
A17: =A16+1 -> 108 | B17: ― | C17: ― | D17: ― | E17: ― | F17: ― | G17: 0.5深0.5 | H17: ― | I17: ― | J17: ― | K17: ― | O17: =A17-100 -> 8 | P17: E2判別 | Q17: 1 | R17: E2判別 | S17: 1 | T17: E2判別
A18: =A17+1 -> 109 | B18: ― | C18: ― | D18: ― | E18: 0.5深0.5 | F18: 0.5深0.5 | G18: 0.5深0.5 | H18: 0.5深0.5 | I18: 0.5深0.5 | J18: ― | K18: ― | O18: =A18-100 -> 9 | P18: D-G原點 | Q18: 1 | R18: DG原點 | S18: 1 | T18: DG原點
A19: =A18+1 -> 110 | B19: ― | C19: ― | D19: ― | E19: 0.5深0.5 | F19: ― | G19: ― | H19: ― | I19: 0.5深0.5 | J19: ― | K19: 0.5深0.5 | O19: =A19-100 -> 10 | P19: △Mark | Q19: 6 | R19: MARK | S19: 6 | T19: MARK
A20: =A19+1 -> 111 | B20: ― | C20: ― | D20: ― | E20: 2 | F20: 2 | G20: 2 | H20: 2 | I20: 2 | J20: ― | K20: 2 | O20: =A20-100 -> 11 | P20: D-G定位PIN | Q20: 4 | R20: DG定位PIN | S20: 4 | T20: DG定位PIN
A21: =A20+1 -> 112 | B21: ― | C21: ― | D21: ― | E21: 2 | F21: 2 | G21: 2 | H21: 2 | I21: 2.0深4.5 /1.95 | J21: ― | K21: 2.2 | O21: =A21-100 -> 12 | P21: UV定位PIN | Q21: 4 | R21: UV定位PIN | S21: 4 | T21: UV定位PIN
A22: =A21+1 -> 113 | B22: {=_xlfn._xlws.FILTER('40-3.5-20L'!AR:BD,'40-3.5-20L'!BD:BD='top-nc'!P22)} -> ― | C22: ― | D22: ― | E22: ― | F22: ― | G22: ― | H22: ― | I22: ― | J22: ― | K22: 3.03 | L22: 3 | M22: --- | N22: 3.0定位PIN(外) | O22: =A22-100 -> 13 | P22: =R22 -> 3.0定位PIN(外) | Q22: 3 | R22: 3.0定位PIN(外) | S22: 3 | T22: 3.0定位PIN(外)
A23: =A22+1 -> 114 | B23: ― | C23: ― | D23: ― | E23: M1.7攻牙 | F23: M1.7攻牙 | G23: M1.7攻牙 | H23: M1.7 裏沈頭 | I23: ― | J23: ― | K23: ― | O23: =A23-100 -> 14 | P23: D-F螺絲 | Q23: 6 | R23: DF螺絲 | S23: 14 | T23: DF螺絲
A24: =A23+1 -> 115 | B24: ― | C24: ― | D24: ― | E24: ― | F24: ― | G24: ― | H24: ― | I24: M1.7沈頭 | J24: ― | K24: M1.7攻牙 | O24: =A24-100 -> 15 | P24: G-H螺絲 | Q24: 6 | R24: GH螺絲 | S24: 16 | T24: GH螺絲
A25: =A24+1 -> 116 | B25: ― | C25: ― | D25: ― | E25: 6 | F25: 6.0深1.5/ 3.2 | G25: 3.2 | H25: 3.2 | I25: 3.2 | J25: ― | K25: M3襯套 | O25: =A25-100 -> 16 | P25: UV螺絲襯套 | Q25: 4 | R25: UV-M3 | S25: 4 | T25: UV螺絲襯套
A26: =A25+1 -> 117 | B26: ― | C26: ― | D26: ― | E26: 1.8 | F26: 1.8 | G26: 1.8 | H26: M1.7 裏沈頭 | I26: ― | J26: ― | K26: ― | O26: =A26-100 -> 17 | P26: 手檔板螺絲 | Q26: 4 | R26: 手檔板螺絲 | S26: 4 | T26: 手檔板螺絲
A27: =A26+1 -> 118 | B27: ― | C27: ― | D27: ― | E27: ― | F27: ― | G27: ― | H27: ― | I27: ― | J27: ― | K27: 3.0深0.5 | O27: =A27-100 -> 18 | P27: H原點 | Q27: 1 | R27: H原點
A28: =A27+1 -> 119 | B28: ― | C28: ― | D28: ― | E28: ― | F28: ― | G28: ― | H28: ― | I28: ― | J28: ― | K28: M3沈頭 | O28: =A28-100 -> 19 | P28: H螺絲 | Q28: 8 | R28: H螺絲
A29: =A28+1 -> 120 | B29: ― | C29: ― | D29: ― | E29: ― | F29: ― | G29: ― | H29: ― | I29: ― | J29: ― | K29: 3 | O29: =A29-100 -> 20 | P29: H3.0定位PIN | Q29: 4 | R29: H定位PIN3.0
A30: =A29+1 -> 121 | B30: {=_xlfn._xlws.FILTER('40-3.5-20L'!P:AB,'40-3.5-20L'!AB:AB='top-nc'!P30)} -> ― | C30: ― | D30: ― | E30: ― | F30: ― | G30: ― | H30: ― | I30: M1.7沈頭 | J30: 6.5 | K30: 3.5 | L30: 3 | M30: 75.3 | N30: G支柱-3.5 | O30: =A30-100 -> 21 | P30: =R30 -> G支柱-3.5 | Q30: 4 | R30: G支柱-3.5
A31: =A30+1 -> 122 | B31: ○ | E31: A板針點請加深0.07 | P31: ABC40 | Q31: 2526 | R31: A
A32: =A31+1 -> 123 | C32: ○ | P32: B40 | Q32: 2526 | R32: B
A33: =A32+1 -> 124 | D33: ○ | P33: C40 | Q33: 2526 | R33: C
A34: =A33+1 -> 125 | E34: ○ | P34: D40 | Q34: 2526 | R34: D-40
A35: =A34+1 -> 126 | F35: ○ | P35: E40 | Q35: 2526 | R35: E-40
A36: =A35+1 -> 127 | G36: ○ | P36: E2-40 | Q36: 2526 | R36: E2-40
A37: =A36+1 -> 128 | H37: ○ | I37: ○ φ1.5裏挖槽 | J37: (線φ | K37: =表頭!J8 -> 0.06 | O37: ） | P37: F,G40 | Q37: 2526 | R37: FG-40
A38: 機台NO
A39: 作業者
C40: 鑽孔用尺寸
A41: 板材 | C41: 100 | D41: x | E41: 100 | G41: 成型尺寸 | J41: Min Pitch | P41: 40
...

Sheet bot-nc
B1: NC DATＡ 管理表 | J1: =表頭!B3 -> WD-2601007
A2: 客戶名稱 | C2: =表頭!I2 -> 景碩科技 清華廠 | G2: 製 作 日 期 | J2: =TODAY() -> 46027
A3: 料 號 | C3: =表頭!B4 -> Q59-859-1(2+4W) | G3: 治 具 型 式 | J3: =表頭!H4 -> Gats-77XX | O3: 下治具
A4: 設 計 者 | C4: KS | G4: 鑽孔檔案名稱 | J4: =表頭!C15 -> O2601007.B
A5: 版 本 | C5: GATS-70 | G5: USB NO.
A7: 板材 | B7: W1000 | C7: R8220 | D7: R8220 | E7: PPS | F7: PPS | G7: PPS | H7: PPS | I7: FR4 | J7: FR4 | K7: BOM | L7: BOM | M7: 内容 | O7: 内容 | P7: 數量
A8: 板厚 | B8: 1.6 | C8: 0.8 | D8: 1 | E8: 3 | F8: 1.5 | G8: 3 | H8: 5 | I8: 1 | J8: 10 | K8: 支柱尺寸 | L8: 支柱長度
A9: O NO | B9: A | C9: B | D9: C | E9: D | F9: E | G9: F | H9: G | I9: G1 | J9: H | N9: T NO
A10: 301 | B10: 0.5深0.5 | C10: 0.5深0.5 | D10: 0.5深0.5 | E10: ― | F10: ― | G10: ― | H10: ― | I10: 1.0深0.5 | J10: ― | N10: =A10-300 -> 1 | O10: ABC原點 | P10: 1 | Q10: ABC原點 | S10: 1 | T10: ABC原點
A11: =A10+1 -> 302 | B11: ○ | C11: ○ | D11: ○ | E11: ○ | F11: ○ | G11: ○ | H11: ○ | I11: ― | J11: ― | N11: =A11-300 -> 2 | O11: 測量用 | P11: 4 | Q11: 測量用 | S11: 4 | T11: 測量用
A12: =A11+1 -> 303 | B12: {=_xlfn._xlws.FILTER('70-30L'!AA:AL,'70-30L'!AL:AL='bot-nc'!O12)} -> 2 | C12: 2 | D12: 2 | E12: 2 | F12: 2 | G12: 2 | H12: ― | I12: 2 | J12: ― | K12: 2 | L12: 29 | M12: AF定位PIN-2.0 | N12: =A12-300 -> 3 | O12: =Q12 -> AF定位PIN-2.0 | P12: 4 | Q12: AF定位PIN-2.0 | S12: 4 | T12: AF定位PIN-2.0
A13: =A12+1 -> 304 | B13: {=_xlfn._xlws.FILTER('70-30L'!A:L,'70-30L'!L:L='bot-nc'!O13)} -> M1.7沈頭 | C13: 1.8 | D13: 1.8 | E13: 1.8 | F13: 1.8 | G13: M1.7 裏沈頭 | H13: ― | I13: ― | J13: ― | K13: 3 | L13: 18.9 | M13: CD支柱-3.0 | N13: =A13-300 -> 4 | O13: =Q13 -> CD支柱-3.0 | P13: 6 | Q13: CD支柱-3.0 | S13: 8 | T13: CD支柱-3.0
A14: =A13+1 -> 305 | B14: 2.0深0.4 /1.2 | C14: 1.3 | D14: 1 | E14: ― | F14: ― | G14: ― | H14: ― | I14: ― | J14: ― | N14: =A14-300 -> 5 | O14: 1.2 CCD | P14: 2 | Q14: 1.2 CCD | S14: 2 | T14: 1.2 CCD
A15: =A14+1 -> 306 | B15: ― | C15: ― | D15: 0.5深0.5 | E15: ― | F15: ― | G15: ― | H15: ― | I15: ― | J15: ― | N15: =A15-300 -> 6 | O15: C判別 | P15: 1 | Q15: C判別 | S15: 1 | T15: C判別
A16: =A15+1 -> 307 | B16: ― | C16: ― | D16: ― | E16: 0.5深0.5 | F16: 0.5深0.5 | G16: 0.5深0.5 | H16: 0.5深0.5 | I16: ― | J16: ― | N16: =A16-300 -> 7 | O16: D-G原點 | P16: 1 | Q16: D-g原點 | S16: 1 | T16: D-g原點
A17: =A16+1 -> 308 | B17: ― | C17: ― | D17: ― | E17: 0.5深0.5 | F17: ― | G17: ― | H17: 0.5深0.5 | I17: ― | J17: 0.5深0.5 | N17: =A17-300 -> 8 | O17: △Mark | P17: 6 | Q17: △Mark | S17: 6 | T17: △Mark
A18: =A17+1 -> 309 | B18: ― | C18: ― | D18: ― | E18: 2 | F18: 2 | G18: 2 | H18: 2 | I18: ― | J18: 2 | N18: =A18-300 -> 9 | O18: D-G定位PIN | P18: 4 | Q18: D-G定位PIN | S18: 4 | T18: D-G定位PIN
A19: =A18+1 -> 310 | B19: ― | C19: ― | D19: ― | E19: 2 | F19: 2 | G19: 2 | H19: 2.0深4.5 /1.95 | I19: ― | J19: 2.2 | N19: =A19-300 -> 10 | O19: UV定位PIN | P19: 4 | Q19: UV定位PIN | S19: 4 | T19: UV定位PIN
A20: =A19+1 -> 311 | B20: {=_xlfn._xlws.FILTER('70-30L'!AN:AY,'70-30L'!AY:AY='bot-nc'!O20)} -> ― | C20: ― | D20: ― | E20: ― | F20: ― | G20: ― | H20: ― | I20: ― | J20: 3.03 | K20: 3 | L20: --- | M20: 3.0定位PIN(外) | N20: =A20-300 -> 11 | O20: =Q20 -> 3.0定位PIN(外) | P20: 3 | Q20: 3.0定位PIN(外) | S20: 3 | T20: 3.0定位PIN(外)
A21: =A20+1 -> 312 | B21: ― | C21: ― | D21: ― | E21: M1.7攻牙 | F21: M1.7攻牙 | G21: M1.7 裏沈頭 | H21: ― | I21: ― | J21: ― | N21: =A21-300 -> 12 | O21: D-F螺絲 | P21: 6 | Q21: D-F螺絲 | S21: 12 | T21: D-F螺絲
A22: =A21+1 -> 313 | B22: ― | C22: ― | D22: ― | E22: ― | F22: ― | G22: ― | H22: M1.7沈頭 | I22: ― | J22: M1.7攻牙 | N22: =A22-300 -> 13 | O22: G-H螺絲 | P22: 6 | Q22: G-H螺絲 | S22: 18 | T22: G-H螺絲
A23: =A22+1 -> 314 | B23: ― | C23: ― | D23: ― | E23: 6 | F23: 3.2 | G23: 3.2 | H23: 3.2 | I23: ― | J23: M3襯套 | N23: =A23-300 -> 14 | O23: UV螺絲襯套 | P23: 4 | Q23: UV螺絲襯套 | S23: 4 | T23: UV螺絲襯套
A24: =A23+1 -> 315 | B24: ― | C24: ― | D24: ― | E24: 1.8 | F24: 1.8 | G24: M1.7 裏沈頭 | H24: ― | I24: ― | J24: ― | N24: =A24-300 -> 15 | O24: 手檔板螺絲 | P24: 4 | Q24: 手檔板螺絲 | S24: 4 | T24: 手檔板螺絲
A25: =A24+1 -> 316 | B25: ― | C25: ― | D25: ― | E25: ― | F25: ― | G25: ― | H25: ― | I25: ― | J25: 3.0深0.5 | N25: =A25-300 -> 16 | O25: H原點 | P25: 1 | Q25: H原點 | S25: 1 | T25: H原點
A26: =A25+1 -> 317 | B26: ― | C26: ― | D26: ― | E26: ― | F26: ― | G26: ― | H26: ― | I26: ― | J26: M3沈頭 | N26: =A26-300 -> 17 | O26: H螺絲 | P26: 8 | Q26: H螺絲 | S26: 8 | T26: H螺絲
A27: =A26+1 -> 318 | B27: ― | C27: ― | D27: ― | E27: ― | F27: ― | G27: ― | H27: ― | I27: ― | J27: 3 | N27: =A27-300 -> 18 | O27: H3.0定位PIN | P27: 4 | Q27: H3.0定位PIN | S27: 4 | T27: H3.0定位PIN
A28: =A27+1 -> 319 | B28: {=_xlfn._xlws.FILTER('70-30L'!N:Y,'70-30L'!Y:Y='bot-nc'!O28)} -> ― | C28: ― | D28: ― | E28: ― | F28: ― | G28: ― | H28: M1.7沈頭 | I28: 6.5 | J28: 3.5 | K28: 3 | L28: 65.3 | M28: G支柱-3.5 | N28: =A28-300 -> 19 | O28: =Q28 -> G支柱-3.5 | P28: 4 | Q28: G支柱-3.5 | S28: 6 | T28: G支柱-3.5
A29: =A28+1 -> 320 | B29: 0.3深0.07 | C29: ― | D29: ― | E29: ― | J29: ― | N29: =A29-300 -> 20 | O29: 反沾逃孔 | P29: 1645 | Q29: 反沾逃孔 | S29: 5777 | T29: 反沾逃孔
A30: =A29+1 -> 321 | B30: ○ | C30: ○ | D30: ○ | E30: A板針點請加深0.07 | O30: ABC70 | P30: 706 | Q30: A | S30: 1736 | T30: A
A31: =A30+1 -> 322 | E31: ○ | O31: D70 | P31: 706 | Q31: D | S31: 1736 | T31: D
A32: =A31+1 -> 323 | F32: ○ | O32: E70 | P32: 706 | Q32: E | S32: 1736 | T32: E
A33: =A32+1 -> 324 | G33: ○ | H33: ○ φ1.5裏挖槽 | I33: (線φ | J33: =表頭!L8 -> 0.12 | N33: ） | O33: F,G70 | P33: 706 | Q33: F | S33: 1736 | T33: F
A34: 機台NO
A35: 作業者
C36: 鑽孔用尺寸
A37: 板材 | C37: 100 | D37: x | E37: 100 | G37: 成型尺寸 | I37: Min Pitch | O37: 70
A38: ABC尺寸 | C38: X: | D38: 46 | E38: SET | F38: 22 | G38: x | H38: 32 | I38: ABC | O38: 0.1
A39: 板材 | C39: 100 | D39: x | E39: 100 | G39: 成型尺寸 | I39: D | O39: 0.175449
A40: D-G(G1)尺寸 | C40: X: | D40: 46 | E40: SET | F40: 36 | G40: x | H40: 36 | I40: E | O40: 0.196245
A41: 板材 | C41: 100 | D41: x | E41: 100 | G41: 成型尺寸 | I41: FG | O41: 0.212603
...

Sheet bom表
A1: 睿智精密股份有限公司 BOM表
A2: 工 單 號: | C2: =表頭!B3 -> WD-2601007 | I2: 客戶名稱： | J2: =LIST!F1 -> 景碩科技 清華廠
A3: 客戶料號: | C3: =表頭!B4 -> Q59-859-1(2+4W) | K3: BOM表編號：
A5: 項目 | B5: 料號 | D5: 品名 | M5: 加工方式 | N5: 數量
B6: 上治具
A7: 1 | B7: A | D7: ='top-nc'!B7 -> SCM8000 | E7: ='top-nc'!B8 -> 1.5 | F7: T | G7: 14 | H7: x | I7: 28 | M7: NC、CNC | N7: 1
A8: =A7+1 -> 2 | B8: B | D8: ='top-nc'!C7 -> SCM8000 | E8: ='top-nc'!C8 -> 1 | F8: T | G8: =G7 -> 14 | H8: x | I8: =I7 -> 28 | M8: NC、CNC | N8: 1
A9: =A8+1 -> 3 | B9: C | D9: ='top-nc'!D7 -> SCM8000 | E9: ='top-nc'!D8 -> 0.8 | F9: T | G9: =G7 -> 14 | H9: x | I9: =I7 -> 28 | M9: NC、CNC | N9: 1
A10: =A9+1 -> 4 | B10: D | D10: ='top-nc'!E7 -> R8220 | E10: ='top-nc'!E8 -> 1.5 | F10: T | G10: 36 | H10: x | I10: 36 | M10: NC、CNC | N10: 1
A11: =A10+1 -> 5 | B11: E | D11: ='top-nc'!F7 -> R8220 | E11: ='top-nc'!F8 -> 3 | F11: T | G11: =G10 -> 36 | H11: x | I11: =I10 -> 36 | M11: NC、CNC | N11: 1
A12: =A11+1 -> 6 | B12: E2 | D12: ='top-nc'!G7 -> R8220 | E12: ='top-nc'!G8 -> 1.5 | F12: T | G12: =G11 -> 36 | H12: x | I12: =I11 -> 36 | M12: NC、CNC | N12: 1
A13: =A12+1 -> 7 | B13: F | D13: ='top-nc'!H7 -> R8220 | E13: ='top-nc'!H8 -> 1.5 | F13: T | G13: =G12 -> 36 | H13: x | I13: =I12 -> 36 | M13: NC、CNC | N13: 1
A14: =A13+1 -> 8 | B14: G | D14: ='top-nc'!I7 -> R8220 | E14: ='top-nc'!I8 -> 5 | F14: T | G14: =G13 -> 36 | H14: x | I14: =I13 -> 36 | M14: NC、CNC | N14: 1
A15: =A14+1 -> 9 | B15: G1 | D15: ='top-nc'!J7 -> FR4 | E15: ='top-nc'!J8 -> 1 | F15: T | G15: 36 | H15: x | I15: 36 | M15: NC、CNC | N15: 1
A16: =A15+1 -> 10 | B16: H | D16: ='top-nc'!K7 -> FR4 | E16: ='top-nc'!K8 -> 10 | F16: T | G16: ='top-nc'!F46 -> 80 | H16: x | I16: ='top-nc'!I46 -> 80 | M16: CNC | N16: 1
A17: =A16+1 -> 11 | D17: 襯套 | E17: ='top-nc'!K25 -> M3襯套 | M17: NC | N17: ='top-nc'!Q25 -> 4
A18: =A17+1 -> 12 | C18: 15040002 | D18: GATS CCD對位PIN | E18: CS97055P0-A05(粗紋) | M18: 組裝 | N18: ='top-nc'!Q15 -> 2
A19: =A18+1 -> 13 | D19: ='top-nc'!P12 -> AF定位PIN-2.0 | E19: ψ | F19: ='top-nc'!L12 -> 2 | H19: L= | I19: ='top-nc'!M12 -> 19 | K19: mm | M19: 組裝 | N19: ='top-nc'!Q12 -> 4
A20: =A19+1 -> 14 | D20: ='top-nc'!P14 -> CD支柱-3.0 | E20: ψ | F20: ='top-nc'!L14 -> 3 | G20: L= | H20: ='top-nc'!M14 -> 9.1 | J20: mm | M20: 組裝 | N20: ='top-nc'!Q14 -> 6
A21: =A20+1 -> 15 | D21: ='top-nc'!P30 -> G支柱-3.5 | E21: ψ | F21: ='top-nc'!L30 -> 3 | G21: L= | H21: ='top-nc'!M30 -> 75.3 | J21: mm | M21: 組裝 | N21: ='top-nc'!Q30 -> 4
A22: =A21+1 -> 16 | D22: 線針 CT46 | E22: =表頭!B8 -> 40N(3.5) | M22: 組裝 | N22: =表頭!C8 -> 2526
A23: =A22+1 -> 17 | D23: 熱縮套管 | E23: F34,ψ1.0 （切10mm） | M23: 組裝 | N23: 2526
A24: =A23+1 -> 18 | D24: 漆包線 | E24: ψ | F24: =表頭!J8 -> 0.06 | H24: L=600mm | M24: 組裝 | N24: 2526
A25: =A24+1 -> 19 | D25: 針盤 | E25: =表頭!I9 -> DD(Full) | M25: 組裝 | N25: =表頭!J9 -> 1
A26: =A25+1 -> 20 | D26: 針盤 | E26: =表頭!I10 -> DD(HALF) | M26: 組裝 | N26: =表頭!J10 -> 1
A27: =A26+1 -> 21 | C27: 15280030 | D27: GATS城堡 | E27: 80X80 4PCS 電木板組成-L=65.3 | M27: CNC、組裝 | N27: 1組
A28: =A27+1 -> 22 | C28: 15160024 | D28: GATS線蓋(後)塑膠-無鎖附 | E28: 奇美耐衝擊訂製 | M28: CNC、組裝 | N28: 1組
A29: =A28+1 -> 23 | C29: 15160022 | D29: GATS_透明壓克力保護蓋(PS塑膠) | E29: 100*100 | M29: CNC、組裝 | N29: 1組
A30: =A29+1 -> 24 | B30: 加工 | C30: 15110002 | D30: GATS底板15t*250*425 | E30: 15t*250*425 | M30: CNC、組裝 | N30: 1
A31: =A30+1 -> 25 | B31: 15060004 | D31: 不鏽鋼灣型手E-40100-9 | E31: SPC-888-100-M4 H47 | M31: CNC、組裝 | N31: 1組
A32: =A31+1 -> 26 | C32: 14115512 | D32: 針盤蓋板(鎖4角) | E32: 透明壓克力5T*150*250mm | M32: CNC、組裝 | N32: 1
A33: =A32+1 -> 27 | D33: 手檔板 | E33: PPS 3T | G33: x | H33: 3x28 | M33: CNC、組裝 | N33: 2
B34: 下治具
A35: 1 | B35: A | D35: ='bot-nc'!B7 -> W1000 | E35: ='bot-nc'!B8 -> 1.6 | F35: T | G35: 14 | H35: x | I35: 28 | M35: NC、CNC | N35: 1
A36: =A35+1 -> 2 | B36: B | D36: ='bot-nc'!C7 -> R8220 | E36: ='bot-nc'!C8 -> 0.8 | F36: T | G36: =G35 -> 14 | H36: x | I36: =I35 -> 28 | M36: NC、CNC | N36: 1
A37: =A36+1 -> 3 | B37: C | D37: ='bot-nc'!D7 -> R8220 | E37: ='bot-nc'!D8 -> 1 | F37: T | G37: =G35 -> 14 | H37: x | I37: =I35 -> 28 | M37: NC、CNC | N37: 1
A38: =A37+1 -> 4 | B38: D | D38: ='bot-nc'!E7 -> PPS | E38: ='bot-nc'!E8 -> 3 | F38: T | G38: 36 | H38: x | I38: 36 | M38: NC、CNC | N38: 1
A39: =A38+1 -> 5 | B39: E | D39: ='bot-nc'!F7 -> PPS | E39: ='bot-nc'!F8 -> 1.5 | F39: T | G39: =G38 -> 36 | H39: x | I39: =I38 -> 36 | M39: NC、CNC | N39: 1
A40: =A39+1 -> 6 | B40: F | D40: ='bot-nc'!G7 -> PPS | E40: ='bot-nc'!G8 -> 3 | F40: T | G40: =G39 -> 36 | H40: x | I40: =I39 -> 36 | M40: NC、CNC | N40: 1
A41: =A40+1 -> 7 | B41: G | D41: ='bot-nc'!H7 -> PPS | E41: ='bot-nc'!H8 -> 5 | F41: T | G41: =G40 -> 36 | H41: x | I41: =I40 -> 36 | M41: NC、CNC | N41: 1
...

Sheet 委外單
A2: 委外加工單
E3: 客戶名稱： | F3: =LIST!F1 -> 景碩科技 清華廠
A4: 供應商：正軒 | C4: 發包日期： | D4: =TODAY() -> 46027 | E4: 工單號： | F4: =表頭!B3 -> WD-2601007
B5: 加工物件名稱 | C5: 數量 | D5: 委托加工內容 (有無G支柱) | E5: 完成日期 | F5: 採購確認 (有無透明片) (100*100) | G5: 簽收者 | H5: 規格(城堡大小) | K5: 底板規格 | M5: 料號工單 | N5: 料號單價
A6: 1 | B6: TOP-I板 | C6: 1 | D6: 製作 | E6: =TODAY()+1 -> 46028 | H6: ='top-nc'!F46 -> 80 | I6: X | J6: ='top-nc'!I46 -> 80
A8: 2 | B8: BOT-I板 | C8: 1 | D8: 製作 | E8: =TODAY()+1 -> 46028 | H8: ='bot-nc'!F42 -> 80 | I8: X | J8: ='bot-nc'!H42 -> 80
A10: 3
A11: 4
A12: 5
A13: 6
A14: 7
A15: 8
A16: 9
A17: 10
A18: 11
A19: 12
A20: 13
A21: 14
... A25: 18
C26: 主管核準： | G26: 製單者： | J26: KS
J27: 表單編號Q-QP-802-07 版次：A

Sheet LIST
A1: 7 | B1: 1/3 | C1: 1/11 | D1: 1/12 | E1: WD-2601007 | F1: 景碩科技 清華廠 | G1: Q59-859-1(2+4W) | H1: Gats-77XX | I1: 7x9x2 | J1: 1x1 | K1: 40N | L1: 2526 | N1: DD*2 | O1: 70N | P1: 706 | R1: DD | S1: HSU | T1: 0105 1500 | W1: 宗智

Sheet 40-3.5-20L
B1: SCM8000 | C1: SCM8000 | D1: SCM8000 | E1: R8220 | F1: R8220 | G1: R8220 | H1: R8220 | I1: R8220 | J1: FR4 | K1: FR4 | L1: BOM | M1: BOM | N1: 内容 | P1: SCM8000 | Q1: SCM8000 | R1: SCM8000 | S1: R8220 | T1: R8220 | U1: R8220 | V1: R8220 | W1: R8220 | X1: FR4 | Y1: FR4 | Z1: BOM | AA1: BOM | AB1: 内容 | AD1: SCM8000 | AE1: SCM8000 | AF1: SCM8000 | AG1: R8220 | AH1: R8220 | AI1: R8220 | AJ1: R8220 | AK1: R8220 | AL1: FR4 | AM1: FR4 | AN1: BOM | AO1: BOM | AP1: 内容 | AR1: SCM8000 | AS1: SCM8000 | AT1: SCM8000 | AU1: R8220 | AV1: R8220 | AW1: R8220 | AX1: R8220 | AY1: R8220 | AZ1: FR4 | BA1: FR4 | BB1: BOM | BC1: BOM | BD1: 内容
B2: 1.5 | C2: 1 | D2: 0.8 | E2: 1.5 | F2: 3 | G2: 1.5 | H2: 1.5 | I2: 5 | J2: 1 | K2: 10 | L2: 支柱尺寸 | M2: 支柱長度 | P2: 1.5 | Q2: 1 | R2: 0.8 | S2: 1.5 | T2: 3 | U2: 1.5 | V2: 1.5 | W2: 5 | X2: 1 | Y2: 10 | Z2: 支柱尺寸 | AA2: 支柱長度 | AD2: 1.5 | AE2: 1 | AF2: 0.8 | AG2: 1.5 | AH2: 3 | AI2: 1.5 | AJ2: 1.5 | AK2: 5 | AL2: 1 | AM2: 10 | AN2: 支柱尺寸 | AO2: 支柱長度 | AR2: 1.5 | AS2: 1 | AT2: 0.8 | AU2: 1.5 | AV2: 3 | AW2: 1.5 | AX2: 1.5 | AY2: 5 | AZ2: 1 | BA2: 10 | BB2: 支柱尺寸 | BC2: 支柱長度
B3: A | C3: B | D3: C | E3: D | F3: E | G3: E2 | H3: F | I3: G | J3: G1 | K3: H | P3: A | Q3: B | R3: C | S3: D | T3: E | U3: E2 | V3: F | W3: G | X3: G1 | Y3: H | AD3: A | AE3: B | AF3: C | AG3: D | AH3: E | AI3: E2 | AJ3: F | AK3: G | AL3: G1 | AM3: H | AR3: A | AS3: B | AT3: C | AU3: D | AV3: E | AW3: E2 | AX3: F | AY3: G | AZ3: G1 | BA3: H
B4: M1.7沈頭 | C4: 1.8 | D4: 1.8 | E4: 1.8 | F4: 1.8 | G4: 1.8 | H4: M1.7 裏沈頭 | I4: ― | J4: ― | K4: ― | L4: 3 | M4: 9.1 | N4: CD支柱-3.0 | P4: ― | Q4: ― | R4: ― | S4: ― | T4: ― | U4: ― | V4: ― | W4: M1.7沈頭 | X4: 6.5 | Y4: 3.5 | Z4: 3 | AA4: 75.3 | AB4: G支柱-3.5 | AD4: 2 | AE4: 2 | AF4: 2 | AG4: 2 | AH4: 2 | AI4: 2 | AJ4: 2 | AK4: ― | AL4: 2 | AM4: ― | AN4: 2 | AO4: 19 | AP4: AF定位PIN-2.0 | AR4: ― | AS4: ― | AT4: ― | AU4: ― | AV4: ― | AW4: ― | AX4: ― | AY4: ― | AZ4: ― | BA4: 3.03 | BB4: 3 | BC4: --- | BD4: 3.0定位PIN(外)
B5: M1.4沈頭 | C5: 1.5 | D5: 1.5 | E5: 1.5 | F5: 1.5 | G5: 1.5 | H5: M1.4 裏沈頭 | I5: ― | J5: ― | K5: ― | L5: 2 | M5: 9.1 | N5: CD支柱-2.0 | P5: ― | Q5: ― | R5: ― | S5: ― | T5: ― | U5: ― | V5: ― | W5: M1.4沈頭 | X5: 6.5 | Y5: 2.5 | Z5: 2 | AA5: =AA4 -> 75.3 | AB5: G支柱-2.5 | AD5: 1.5 | AE5: 1.5 | AF5: 1.5 | AG5: 1.5 | AH5: 1.5 | AI5: 1.5 | AJ5: 1.5 | AK5: ― | AL5: 1.5 | AM5: ― | AN5: 1.5 | AO5: 19 | AP5: AF定位PIN-1.5 | AR5: ― | AS5: ― | AT5: ― | AU5: 3.03 | AV5: 3.03 | AW5: 3.03 | AX5: 3.03 | AY5: 3.03 | AZ5: ― | BA5: 3.03 | BB5: 3 | BC5: --- | BD5: 3.0定位PIN(內)
B6: 裏0.6深0.5 | C6: 0.6 | D6: 0.6 | E6: 0.6 | F6: ― | G6: ― | H6: ― | I6: ― | J6: ― | K6: ― | L6: 1 | M6: 9.1 | N6: CD支柱-1.0 | P6: ― | Q6: ― | R6: ― | S6: ― | T6: ― | U6: ― | V6: ― | W6: M1.7沈頭 | X6: 6.5 | Y6: ― | Z6: 3 | AA6: =AA5 -> 75.3 | AB6: G支柱-3.0
B7: 裏0.6深0.3 | C7: 0.3 | D7: 0.3 | E7: 0.3 | F7: ― | G7: ― | H7: ― | I7: ― | J7: ― | K7: ― | L7: 0.5 | M7: 9.1 | N7: CD支柱-0.5 | P7: ― | Q7: ― | R7: ― | S7: ― | T7: ― | U7: ― | V7: ― | W7: M1.4沈頭 | X7: 6.5 | Y7: ― | Z7: 2 | AA7: =AA6 -> 75.3 | AB7: G支柱-2.0
B8: M1.7 裏沈頭逃孔 | C8: 1.8 | D8: 1.8 | E8: 1.8 | F8: 1.8 | G8: 1.8 | H8: M1.7 裏沈頭 | I8: ― | J8: ― | K8: ― | L8: 3 | M8: 9.1 | N8: CD-B支柱-3.0 | P8: ― | Q8: ― | R8: ― | S8: ― | T8: ― | U8: ― | V8: ― | W8: 0.8 | X8: 6.5 | Y8: ― | Z8: 0.8 | AA8: =AA7 -> 75.3 | AB8: G支柱-0.8
B9: M1.4 裏沈頭逃孔 | C9: 1.5 | D9: 1.5 | E9: 1.5 | F9: 1.5 | G9: 1.5 | H9: M1.4 裏沈頭 | I9: ― | J9: ― | K9: ― | L9: 2 | M9: 9.1 | N9: CD-B支柱-2.0

Sheet 70-30L
A1: W1000 | B1: R8220 | C1: R8220 | D1: R8220 | E1: R8220 | F1: R8220 | G1: R8220 | H1: FR4 | I1: 黑電木 | J1: BOM | K1: BOM | L1: 内容 | N1: W1000 | O1: R8220 | P1: R8220 | Q1: R8220 | R1: R8220 | S1: R8220 | T1: R8220 | U1: FR4 | V1: 黑電木 | W1: BOM | X1: BOM | Y1: 内容 | AA1: W1000 | AB1: R8220 | AC1: R8220 | AD1: R8220 | AE1: R8220 | AF1: R8220 | AG1: R8220 | AH1: FR4 | AI1: 黑電木 | AJ1: BOM | AK1: BOM | AL1: 内容 | AN1: W1000 | AO1: R8220 | AP1: R8220 | AQ1: R8220 | AR1: R8220 | AS1: R8220 | AT1: R8220 | AU1: FR4 | AV1: 黑電木 | AW1: BOM | AX1: BOM | AY1: 内容
A2: 1.6 | B2: 0.8 | C2: 1 | D2: 3 | E2: 1.5 | F2: 3 | G2: 5 | H2: 1 | I2: 10 | J2: 支柱尺寸 | K2: 支柱長度 | N2: 1.6 | O2: 0.8 | P2: 1 | Q2: 3 | R2: 1.5 | S2: 3 | T2: 5 | U2: 1 | V2: 10 | W2: 支柱尺寸 | X2: 支柱長度 | AA2: 1.6 | AB2: 0.8 | AC2: 1 | AD2: 3 | AE2: 1.5 | AF2: 3 | AG2: 5 | AH2: 1 | AI2: 10 | AJ2: 支柱尺寸 | AK2: 支柱長度 | AN2: 1.6 | AO2: 0.8 | AP2: 1 | AQ2: 3 | AR2: 1.5 | AS2: 3 | AT2: 5 | AU2: 1 | AV2: 10 | AW2: 支柱尺寸 | AX2: 支柱長度
A3: A | B3: B | C3: C | D3: D | E3: E | F3: F | G3: G | H3: G1 | I3: H | N3: A | O3: B | P3: C | Q3: D | R3: E | S3: F | T3: G | U3: G1 | V3: H | AA3: A | AB3: B | AC3: C | AD3: D | AE3: E | AF3: F | AG3: G | AH3: G1 | AI3: H | AN3: A | AO3: B | AP3: C | AQ3: D | AR3: E | AS3: F | AT3: G | AU3: G1 | AV3: H
A4: M1.7沈頭 | B4: 1.8 | C4: 1.8 | D4: 1.8 | E4: 1.8 | F4: M1.7 裏沈頭 | G4: ― | H4: ― | I4: ― | J4: 3 | K4: 18.9 | L4: CD支柱-3.0 | N4: ― | O4: ― | P4: ― | Q4: ― | R4: ― | S4: ― | T4: M3沈頭 | U4: 6.5 | V4: 6.5 | W4: 6 | X4: 65.3 | Y4: G支柱-6.5 | AA4: 2 | AB4: 2 | AC4: 2 | AD4: 2 | AE4: 2 | AF4: 2 | AG4: ― | AH4: 2 | AI4: ― | AJ4: 2 | AK4: 29 | AL4: AF定位PIN-2.0 | AN4: ― | AO4: ― | AP4: ― | AQ4: ― | AR4: ― | AS4: ― | AT4: ― | AU4: ― | AV4: 3.03 | AW4: 3 | AX4: --- | AY4: 3.0定位PIN(外)
A5: M1.4沈頭 | B5: 1.5 | C5: 1.5 | D5: 1.5 | E5: 1.5 | F5: M1.4 裏沈頭 | G5: ― | H5: ― | I5: ― | J5: 2 | K5: 18.9 | L5: CD支柱-2.0 | N5: ― | O5: ― | P5: ― | Q5: ― | R5: ― | S5: ― | T5: M1.7沈頭 | U5: 6.5 | V5: 3.5 | W5: 3 | X5: =X4 -> 65.3 | Y5: G支柱-3.5 | AA5: 1.5 | AB5: 1.5 | AC5: 1.5 | AD5: 1.5 | AE5: 1.5 | AF5: 1.5 | AG5: ― | AH5: 1.5 | AI5: ― | AJ5: 1.5 | AK5: 29 | AL5: AF定位PIN-1.5 | AN5: ― | AO5: ― | AP5: ― | AQ5: 3.03 | AR5: 3.03 | AS5: 3.03 | AT5: 3.03 | AU5: ― | AV5: 3.03 | AW5: 3 | AX5: --- | AY5: 3.0定位PIN(內)
A6: 裏0.6深0.5 | B6: 0.6 | C6: 0.6 | D6: 0.6 | E6: ― | F6: ― | G6: ― | H6: ― | I6: ― | J6: 1 | K6: 18.9 | L6: CD支柱-1.0 | N6: ― | O6: ― | P6: ― | Q6: ― | R6: ― | S6: ― | T6: M1.4沈頭 | U6: 6.5 | V6: 2.5 | W6: 2 | X6: =X5 -> 65.3 | Y6: G支柱-2.5
A7: 裏0.6深0.3 | B7: 0.3 | C7: 0.3 | D7: 0.3 | E7: ― | F7: ― | G7: ― | H7: ― | I7: ― | J7: 0.5 | K7: 18.9 | L7: CD支柱-0.5 | N7: ― | O7: ― | P7: ― | Q7: ― | R7: ― | S7: ― | T7: M3沈頭 | U7: 6.5 | V7: ― | W7: 6 | X7: =X6 -> 65.3 | Y7: G支柱-6.0
A8: M1.7 裏沈頭逃孔 | B8: 1.8 | C8: 1.8 | D8: 1.8 | E8: 1.8 | F8: M1.7 裏沈頭 | G8: ― | H8: ― | I8: ― | J8: 3 | K8: 18.9 | L8: CD-B支柱-3.0 | N8: ― | O8: ― | P8: ― | Q8: ― | R8: ― | S8: ― | T8: M1.7沈頭 | U8: 6.5 | V8: ― | W8: 3 | X8: =X7 -> 65.3 | Y8: G支柱-3.0
A9: M1.4 裏沈頭逃孔 | B9: 1.5 | C9: 1.5 | D9: 1.5 | E9: 1.5 | F9: M1.4 裏沈頭 | G9: ― | H9: ― | I9: ― | J9: 2 | K9: 18.9 | L9: CD-B支柱-2.0 | N9: ― | O9: ― | P9: ― | Q9: ― | R9: ― | S9: ― | T9: M1.4沈頭 | U9: 6.5 | V9: ― | W9: 2 | X9: =X8 -> 65.3 | Y9: G支柱-2.0
N10: ― | O10: ― | P10: ― | Q10: ― | R10: ― | S10: ― | T10: 0.8 | U10: 6.5 | V10: ― | W10: 0.8 | X10: =X9 -> 65.3 | Y10: G支柱-0.8
W11: ― | X11: ― | Y11: -------------
